<sdf version="1.6">
  <model name="cyberdisc">
    <link name="base_link">
      <visual>
        <geometry>
          <cylinder radius="0.25" length="0.05"/>
        </geometry>
      </visual>
      <collision>
        <geometry>
          <cylinder radius="0.25" length="0.05"/>
        </geometry>
      </collision>
    </link>
    <link name="motor_0_motor_root">
      <visual>
        <geometry>
          <box size="0.08 0.04 0.03"/>
        </geometry>
      </visual>
      <collision>
        <geometry>
          <box size="0.08 0.04 0.03"/>
        </geometry>
      </collision>
    </link>
    <link name="motor_0_motor_axle">
      <visual>
        <geometry>
          <cylinder radius="0.005" length="0.07"/>
        </geometry>
      </visual>
      <collision>
        <geometry>
          <cylinder radius="0.005" length="0.07"/>
        </geometry>
      </collision>
    </link>
    <link name="motor_0_wheel_link">
      <visual>
        <geometry>
          <cylinder radius="0.04" length="0.02"/>
        </geometry>
      </visual>
      <collision>
        <geometry>
          <cylinder radius="0.04" length="0.02"/>
        </geometry>
      </collision>
    </link>
    <link name="motor_1_motor_root">
      <visual>
        <geometry>
          <box size="0.08 0.04 0.03"/>
        </geometry>
      </visual>
      <collision>
        <geometry>
          <box size="0.08 0.04 0.03"/>
        </geometry>
      </collision>
    </link>
    <link name="motor_1_motor_axle">
      <visual>
        <geometry>
          <cylinder radius="0.005" length="0.07"/>
        </geometry>
      </visual>
      <collision>
        <geometry>
          <cylinder radius="0.005" length="0.07"/>
        </geometry>
      </collision>
    </link>
    <link name="motor_1_wheel_link">
      <visual>
        <geometry>
          <cylinder radius="0.04" length="0.02"/>
        </geometry>
      </visual>
      <collision>
        <geometry>
          <cylinder radius="0.04" length="0.02"/>
        </geometry>
      </collision>
    </link>
    <link name="motor_2_motor_root">
      <visual>
        <geometry>
          <box size="0.08 0.04 0.03"/>
        </geometry>
      </visual>
      <collision>
        <geometry>
          <box size="0.08 0.04 0.03"/>
        </geometry>
      </collision>
    </link>
    <link name="motor_2_motor_axle">
      <visual>
        <geometry>
          <cylinder radius="0.005" length="0.07"/>
        </geometry>
      </visual>
      <collision>
        <geometry>
          <cylinder radius="0.005" length="0.07"/>
        </geometry>
      </collision>
    </link>
    <link name="motor_2_wheel_link">
      <visual>
        <geometry>
          <cylinder radius="0.04" length="0.02"/>
        </geometry>
      </visual>
      <collision>
        <geometry>
          <cylinder radius="0.04" length="0.02"/>
        </geometry>
      </collision>
    </link>
    <link name="motor_3_motor_root">
      <visual>
        <geometry>
          <box size="0.08 0.04 0.03"/>
        </geometry>
      </visual>
      <collision>
        <geometry>
          <box size="0.08 0.04 0.03"/>
        </geometry>
      </collision>
    </link>
    <link name="motor_3_motor_axle">
      <visual>
        <geometry>
          <cylinder radius="0.005" length="0.07"/>
        </geometry>
      </visual>
      <collision>
        <geometry>
          <cylinder radius="0.005" length="0.07"/>
        </geometry>
      </collision>
    </link>
    <link name="motor_3_wheel_link">
      <visual>
        <geometry>
          <cylinder radius="0.04" length="0.02"/>
        </geometry>
      </visual>
      <collision>
        <geometry>
          <cylinder radius="0.04" length="0.02"/>
        </geometry>
      </collision>
    </link>
    <joint name="motor_0_jnt_motor" type="fixed">
      <parent link="motor_0_motor_root"/>
      <child link="motor_0_motor_axle"/>
      <origin xyz="0.04 0.0 0.0" rpy="0.0 1.5707963267948966 0.0"/>
    </joint>
    <joint name="motor_0_jnt_motor_wheel" type="continuous">
      <parent link="motor_0_motor_axle"/>
      <child link="motor_0_wheel_link"/>
      <axis xyz="0 0 1"/>
      <origin xyz="0.0 0.0 0.0" rpy="0.0 0.0 0.0"/>
    </joint>
    <joint name="jnt_motor_0_connect" type="fixed">
      <parent link="base_link"/>
      <child link="motor_0_motor_root"/>
      <origin xyz="0.1 0.1 0.0" rpy="0.0 0.0 1.5707963267948966"/>
    </joint>
    <joint name="motor_1_jnt_motor" type="fixed">
      <parent link="motor_1_motor_root"/>
      <child link="motor_1_motor_axle"/>
      <origin xyz="0.04 0.0 0.0" rpy="0.0 1.5707963267948966 0.0"/>
    </joint>
    <joint name="motor_1_jnt_motor_wheel" type="continuous">
      <parent link="motor_1_motor_axle"/>
      <child link="motor_1_wheel_link"/>
      <axis xyz="0 0 1"/>
      <origin xyz="0.0 0.0 0.0" rpy="0.0 0.0 0.0"/>
    </joint>
    <joint name="jnt_motor_1_connect" type="fixed">
      <parent link="base_link"/>
      <child link="motor_1_motor_root"/>
      <origin xyz="-0.1 0.1 0.0" rpy="0.0 0.0 1.5707963267948966"/>
    </joint>
    <joint name="motor_2_jnt_motor" type="fixed">
      <parent link="motor_2_motor_root"/>
      <child link="motor_2_motor_axle"/>
      <origin xyz="0.04 0.0 0.0" rpy="0.0 1.5707963267948966 0.0"/>
    </joint>
    <joint name="motor_2_jnt_motor_wheel" type="continuous">
      <parent link="motor_2_motor_axle"/>
      <child link="motor_2_wheel_link"/>
      <axis xyz="0 0 1"/>
      <origin xyz="0.0 0.0 0.0" rpy="0.0 0.0 0.0"/>
    </joint>
    <joint name="jnt_motor_2_connect" type="fixed">
      <parent link="base_link"/>
      <child link="motor_2_motor_root"/>
      <origin xyz="-0.1 -0.1 0.0" rpy="0.0 0.0 -1.5707963267948966"/>
    </joint>
    <joint name="motor_3_jnt_motor" type="fixed">
      <parent link="motor_3_motor_root"/>
      <child link="motor_3_motor_axle"/>
      <origin xyz="0.04 0.0 0.0" rpy="0.0 1.5707963267948966 0.0"/>
    </joint>
    <joint name="motor_3_jnt_motor_wheel" type="continuous">
      <parent link="motor_3_motor_axle"/>
      <child link="motor_3_wheel_link"/>
      <axis xyz="0 0 1"/>
      <origin xyz="0.0 0.0 0.0" rpy="0.0 0.0 0.0"/>
    </joint>
    <joint name="jnt_motor_3_connect" type="fixed">
      <parent link="base_link"/>
      <child link="motor_3_motor_root"/>
      <origin xyz="0.1 -0.1 0.0" rpy="0.0 0.0 -1.5707963267948966"/>
    </joint>
  </model>
</sdf>
