<robot name="basic_anthropomorph">
  <link name="base_link">
    <visual>
      <origin xyz="0.0 0.0 0.15"/>
      <geometry>
        <cylinder radius="0.2" length="0.3"/>
      </geometry>
    </visual>
    <collision>
      <origin xyz="0.0 0.0 0.15"/>
      <geometry>
        <cylinder radius="0.2" length="0.3"/>
      </geometry>
    </collision>
    <inertial>
      <mass value="10.0"/>
      <inertia ixx="1.0" ixy="0.0" iyy="1.0" izz="1.0" ixz="0.0" iyz="0.0"/>
    </inertial>
  </link>
  <link name="shoulder_link">
    <visual>
      <origin xyz="0.0 0.0 0.3"/>
      <geometry>
        <cylinder radius="0.15" length="0.1"/>
      </geometry>
    </visual>
    <collision>
      <origin xyz="0.0 0.0 0.3"/>
      <geometry>
        <cylinder radius="0.15" length="0.1"/>
      </geometry>
    </collision>
  </link>
  <link name="arm_link">
    <visual>
      <origin xyz="0.0 0.0 0.3"/>
      <geometry>
        <cylinder radius="0.1" length="0.6"/>
      </geometry>
    </visual>
    <collision>
      <origin xyz="0.0 0.0 0.3"/>
      <geometry>
        <cylinder radius="0.1" length="0.6"/>
      </geometry>
    </collision>
  </link>
  <link name="wrist_link1">
    <visual>
      <origin xyz="0.0 0.0 0.1"/>
      <geometry>
        <cylinder radius="0.1" length="0.1"/>
      </geometry>
    </visual>
    <collision>
      <origin xyz="0.0 0.0 0.1"/>
      <geometry>
        <cylinder radius="0.1" length="0.1"/>
      </geometry>
    </collision>
  </link>
  <link name="wrist_link2">
    <visual>
      <origin xyz="0.0 0.0 0.15"/>
      <geometry>
        <cylinder radius="0.1" length="0.1"/>
      </geometry>
    </visual>
    <collision>
      <origin xyz="0.0 0.0 0.15"/>
      <geometry>
        <cylinder radius="0.1" length="0.1"/>
      </geometry>
    </collision>
  </link>
  <link name="wrist_link3">
    <visual>
      <origin xyz="0.0 0.0 0.15"/>
      <geometry>
        <cylinder radius="0.1" length="0.3"/>
      </geometry>
    </visual>
    <collision>
      <origin xyz="0.0 0.0 0.15"/>
      <geometry>
        <cylinder radius="0.1" length="0.1"/>
      </geometry>
    </collision>
  </link>
  <joint name="jnt_base_shoulder" type="revolute">
    <parent link="base_link"/>
    <child link="shoulder_link"/>
    <axis xyz="0 0 1"/>
    <origin xyz="0.0 0.0 0.1" rpy="0.0 0.0 0.0"/>
    <limit lower="-3.141592653589793" upper="3.141592653589793"/>
  </joint>
  <joint name="jnt_shoulder_arm" type="revolute">
    <parent link="shoulder_link"/>
    <child link="arm_link"/>
    <axis xyz="1 0 0"/>
    <origin xyz="0.0 0.0 0.15" rpy="0.0 0.0 0.0"/>
    <limit lower="-2.0943951023931953" upper="2.0943951023931953"/>
  </joint>
  <joint name="jnt_arm_wrist" type="revolute">
    <parent link="arm_link"/>
    <child link="wrist_link1"/>
    <axis xyz="1 0 0"/>
    <origin xyz="0.0 0.0 0.6" rpy="0.0 0.0 0.0"/>
    <limit lower="-2.0943951023931953" upper="2.0943951023931953"/>
  </joint>
  <joint name="jnt_wrist1_wrist2" type="revolute">
    <parent link="wrist_link1"/>
    <child link="wrist_link2"/>
    <axis xyz="0 0 1"/>
    <origin xyz="0.0 0.0 0.075" rpy="0.0 0.0 0.0"/>
    <limit lower="-2.0943951023931953" upper="2.0943951023931953"/>
  </joint>
  <joint name="jnt_wrist2_wrist3" type="revolute">
    <parent link="wrist_link2"/>
    <child link="wrist_link3"/>
    <axis xyz="1 0 0"/>
    <origin xyz="0.0 0.0 0.075" rpy="0.0 0.0 0.0"/>
    <limit lower="-2.0943951023931953" upper="2.0943951023931953"/>
  </joint>
</robot>
